<robot name = "mrcrabs" xmlns:xacro="http://ros.org/wiki/xacro">
  <xacro:property name = "base_width" value = "0.166"/>
  <xacro:property name = "base_length" value = "0.266"/>
  <xacro:property name = "base_height" value = "0.08"/>
  <xacro:property name = "wheel_radius" value = "0.04"/>
  <xacro:property name = "wheel_width" value = "0.04"/>
  <xacro:property name = "wheel_ygap" value = "0.114"/>
  <xacro:property name = "wheel_zoff" value = "-0.078"/>
  <xacro:property name = "wheel_xoff" value = "0.074"/>
  <xacro:property name = "laser_zoff" value = "0.147"/>
  <xacro:property name = "sonar_size" value = "0.045 0.015 0.02"/>
  <xacro:property name = "sonar_xoff" value = "0.133"/>
  <xacro:property name = "sonar_zoff" value = "0.01"/>
  <xacro:property name = "sonar_yoff" value = "0.083"/>
  <xacro:property name = "kinect_size" value = "0.062 0.280 0.037"/>
  <xacro:property name = "kinect_xoff" value = "0.09"/>
  <xacro:property name = "kinect_zoff" value = "0.07"/>

  <material name = "purple">
    <color rgba = "0.5 0 0.5 1"/>
  </material>

  <material name = "black">
    <color rgba = "0 0 0 1"/>
  </material>

  <material name = "blue">
    <color rgba = "0 0 0.8 1"/>
  </material>

  <link name = "base_link">
    <visual>
      <geometry>
        <box size = "${base_length} ${base_width} ${base_height}"/>
      </geometry>
      <origin rpy = "0 0 3.14159" xyz = "0 0 0"/>
      <material name = "purple"/>
    </visual>
  </link>

  <link name = "base_laser">
    <visual>
      <geometry>
        <cylinder length="0.04" radius = "0.04"/>
      </geometry>
      <origin rpy = "0 0 0" xyz = "0 0 0"/>
      <material name = "blue"/>
    </visual>
  </link>

  <joint name = "laser_joint" type = "fixed">
    <parent link = "base_link"/>
    <child link = "base_laser"/>
    <origin xyz = "-0.07 0 0.10"/>
  </joint>

  <link name = "front_sonar">
    <visual>
      <geometry>
        <box size = "${sonar_size}"/>
      </geometry>
      <origin rpy = "0 0 0" xyz = "0 0 0"/>
      <material name = "black"/>
    </visual>
  </link>

  <joint name = "front_sonar_joint" type = "fixed">
    <parent link = "base_link"/>
    <child link = "front_sonar"/>
    <origin rpy="0 0 0" xyz = "${sonar_xoff} 0 ${sonar_zoff}"/>
  </joint>

  <link name = "back_sonar">
    <visual>
      <geometry>
        <box size = "${sonar_size}"/>
      </geometry>
      <origin rpy = "0 0 0" xyz = "0 0 0"/>
      <material name = "black"/>
    </visual>
  </link>

  <joint name = "back_sonar_joint" type = "fixed">
    <parent link = "base_link"/>
    <child link = "back_sonar"/>
    <origin rpy="0 0 -1.57075" xyz = "-${sonar_xoff} 0 ${sonar_zoff}"/>
  </joint>

  <link name = "left_sonar">
    <visual>
      <geometry>
        <box size = "${sonar_size}"/>
      </geometry>
      <origin rpy = "0 0 0" xyz = "0 0 0"/>
      <material name = "black"/>
    </visual>
  </link>

  <joint name = "left_sonar_joint" type = "fixed">
    <parent link = "base_link"/>
    <child link = "left_sonar"/>
    <origin xyz = " 0 ${sonar_yoff} ${sonar_zoff}"/>
  </joint>

  <link name = "right_sonar">
    <visual>
      <geometry>
        <box size = "${sonar_size}"/>
      </geometry>
      <origin rpy = "0 0 0" xyz = "0 0 0"/>
      <material name = "black"/>
    </visual>
  </link>

  <joint name = "right_sonar_joint" type = "fixed">
    <parent link = "base_link"/>
    <child link = "right_sonar"/>
    <origin xyz = " 0 -${sonar_yoff} ${sonar_zoff}"/>
  </joint>

  <link name = "kinect">
    <visual>
      <geometry>
        <box size = "${kinect_size}"/>
      </geometry>
      <origin rpy = "0 0 0" xyz = "0 0 0"/>
      <material name = "black"/>
    </visual>
  </link>

  <joint name = "kinect_rotate" type = "revolute">
    <axis xyz="0 1 0"/>
    <limit effort="1000.0" lower="-0.471239" upper="0.471239" velocity="0.1"/>
    <parent link = "base_link"/>
    <child link = "kinect"/>
    <origin xyz = "${kinect_xoff} 0 ${kinect_zoff}"/>
  </joint>

  <link name = "fr_wheel">
    <visual>
      <geometry>
        <cylinder length="${wheel_width}" radius = "${wheel_radius}"/>
      </geometry>
      <origin rpy = "1.57075 0 0" xyz = "0 0 0"/>
      <material name = "black"/>
    </visual>
  </link>

  <joint name = "fr_wheel_cont" type = "continuous">
    <axis xyz="0 1 0"/>
    <parent link = "base_link"/>
    <child link = "fr_wheel"/>
    <origin xyz = "${wheel_xoff} ${wheel_ygap} ${wheel_zoff}"/>
  </joint>

  <link name = "fl_wheel">
    <visual>
      <geometry>
        <cylinder length="${wheel_width}" radius = "${wheel_radius}"/>
      </geometry>
      <origin rpy = "1.57075 0 0" xyz = "0 0 0"/>
      <material name = "black"/>
    </visual>
  </link>

  <joint name = "fl_wheel_cont" type = "continuous">
    <axis xyz="0 1 0"/>
    <parent link = "base_link"/>
    <child link = "fl_wheel"/>
    <origin xyz = "${wheel_xoff} -${wheel_ygap} ${wheel_zoff}"/>
  </joint>

  <link name = "br_wheel">
    <visual>
      <geometry>
        <cylinder length="${wheel_width}" radius = "${wheel_radius}"/>
      </geometry>
      <origin rpy = "1.57075 0 0" xyz = "0 0 0"/>
      <material name = "black"/>
    </visual>
  </link>

  <joint name = "br_wheel_cont" type = "continuous">
    <axis xyz="0 1 0"/>
    <parent link = "base_link"/>
    <child link = "br_wheel"/>
    <origin xyz = "-${wheel_xoff} ${wheel_ygap} ${wheel_zoff}"/>
  </joint>

  <link name = "bl_wheel">
    <visual>
      <geometry>
        <cylinder length="${wheel_width}" radius = "${wheel_radius}"/>
      </geometry>
      <origin rpy = "1.57075 0 0" xyz = "0 0 0"/>
      <material name = "black"/>
    </visual>
  </link>

  <joint name = "bl_wheel_cont" type = "continuous">
    <axis xyz="0 1 0"/>
    <parent link = "base_link"/>
    <child link = "bl_wheel"/>
    <origin xyz = "-${wheel_xoff} -${wheel_ygap} ${wheel_zoff}"/>
  </joint>

</robot>
